Workbook

Sheet Customers
A1: CustomerID | B1: CustomerName | C1: Industry | D1: City | E1: Region
A2: C001 | B2: Apollo Hospitals | C2: Healthcare | D2: Chennai | E2: South
A3: C002 | B3: Reliance Retail Ltd | C3: Retail | D3: Mumbai | E3: West
A4: C003 | B4: Tata Steel Limited | C4: Manufacturing | D4: Jamshedpur | E4: East
A5: C004 | B5: Fortis Healthcare | C5: Healthcare | D5: New Delhi | E5: North
A6: C005 | B6: Flipkart Internet Pvt Ltd | C6: E-commerce | D6: Bangalore | E6: South
A7: C006 | B7: Amazon Seller Services Pvt Ltd | C7: E-commerce | D7: Hyderabad | E7: South
A8: C007 | B8: ITC Limited Foods Division | C8: Food | D8: Kolkata | E8: East
A9: C008 | B9: Sun Pharmaceutical Industries | C9: Pharma | D9: Vadodara | E9: West
A10: C009 | B10: Lupin Pharmaceuticals | C10: Pharma | D10: Pune | E10: West
A11: C010 | B11: BigBasket Retail Pvt Ltd | C11: Retail | D11: Bangalore | E11: South

Sheet Employees
A1: EmployeeID | B1: EmployeeName | C1: Role | D1: Region | E1: HireDate
A2: E01 | B2: Rahul Mehta | C2: Logistics Manager | D2: West | E2: 2019-03-12
A3: E02 | B3: Priya Sharma | C3: Operations Analyst | D3: North | E3: 2021-07-22
A4: E03 | B4: Amit Kulkarni | C4: Dispatch Supervisor | D4: West | E4: 2020-01-15
A5: E04 | B5: Neha Verma | C5: Logistics Coordinator | D5: East | E5: 2023-02-18
A6: E05 | B6: Arjun Patel | C6: Warehouse Lead | D6: West | E6: 2018-11-05

Sheet Categories
A1: ProductCategory | B1: TaxRate | C1: HandlingCostPerKG
A2: Electronics | B2: 0.18 | C2: 2.5
A3: Medical Equipment | B3: 0.12 | C3: 2
A4: Industrial Goods | B4: 0.15 | C4: 3
A5: Food Products | B5: 0.05 | C5: 1.5
A6: Pharmaceuticals | B6: 0.1 | C6: 2

Sheet Targets
A1: Region | B1: MonthlyRevenueTarget | C1: MonthlyShipmentTarget
A2: North | B2: 550000 | C2: 120
A3: South | B3: 520000 | C3: 110
A4: East | B4: 460000 | C4: 100
A5: West | B5: 600000 | C5: 130

Sheet Raw Data
A1: ShipmentID | B1: ShipDate | C1: CustomerID | D1: EmployeeID | E1: Region | F1: ProductCategory | G1: DistanceKM | H1: WeightKG | I1: ShippingFee | J1: Discount | K1: Cost | L1: DeliveryDays | M1: PaymentStatus
A2: S001 | B2: 04-19-2025 | C2: C008 | D2: E04 | E2: north | F2: Industrial Goods | G2: 1607 | H2: 421 | I2: 4125.16 | J2: 100 | K2: 2508.64 | L2: 8 | M2: Paid
A3: S002 | B3: 04-06-2025 | C3: C005 | D3: E04 | E3: West | F3: Medical Equipment | G3: 977 | H3: 475 | I3: 3650.61 | J3: 0 | K3: 2887.46 | L3: 1 | M3: Pending
A4: S003 | B4: 15/01/2025 | C4: C006 | D4: E02 | E4: West | F4: Industrial Goods | G4: 541 | H4: 178 | I4: 1786.34 | J4: 50 | K4: 1176.14 | L4: 7 | M4: Paid
A5: S005 | B5: 03/03/2025 | C5: C010 | D5: E03 | E5: West | F5: Medical Equipment | G5: 722 | H5: 164 | I5: 1842.12 | J5: 100 | K5: 1320.36 | L5: 3 | M5: Overdue
A6: S006 | B6: 27/02/2025 | C6: C010 | D6: E01 | E6: south | F6: Pharmaceuticals | G6: 875 | H6: 314 | I6: 2382.2 | J6: 150 | K6: 1540.1 | L6: 2 | M6: Overdue
A7: S007 | B7: 04-05-2025 | C7: C005 | D7: E02 | E7: North | F7: Food Products | G7: 362 | H7: 772 | I7: 5185.91 | J7: 0 | K7: 4314.46 | L7: 8 | M7: Pending
A8: S008 | B8: 24/02/2025 | C8: C010 | D8: E03 | E8: east | F8: Food Products | G8: 1261 | H8: 187 | I8: 1900.42 | J8: 0 | K8: 1536.94 | L8: 6 | M8: Overdue
A9: S009 | B9: 16/04/2025 | C9: C004 | D9: E02 | E9: South | F9: Industrial Goods | G9: 1894 | H9: 607 | I9: 5993.83 | J9: 100 | K9: 4814.13 | L9: 5 | M9: Overdue
A10: S010 | B10: 01-22-2025 | C10: C001 | D10: E04 | E10: north | F10: Electronics | G10: 429 | H10: 539 | I10: 4056 | J10: 100 | K10: 3129.93 | L10: 4 | M10: Pending
A11: S011 | B11: 2025-02-13 | C11: C005 | D11: E01 | E11: East | F11: Electronics | G11: 1327 | H11: 386 | I11: 3651.63 | J11: 150 | K11: 3008.95 | L11: 7 | M11: Pending
A12: S012 | B12: 21/01/2025 | C12: C001 | D12: E02 | E12: South | F12: Medical Equipment | G12: 575 | H12: 207 | I12: 1856.45 | J12: 0 | K12: 1229.75 | L12: 7 | M12: Overdue
A13: S013 | B13: 02-27-2025 | C13: C008 | D13: E02 | E13: West | F13: Industrial Goods | G13: 710 | H13: 148 | I13: 1716.99 | J13: 50 | K13: 1178.48 | L13: 6 | M13: Pending
A14: S014 | B14: 03/03/2025 | C14: C003 | D14: E01 | E14: East | F14: Electronics | G14: 401 | H14: 176 | I14: 1350.24 | J14: 50 | K14: 894.87 | L14: 3 | M14: Pending
A15: S015 | B15: 2025-03-09 | C15: C003 | D15: E03 | E15: north | F15: Pharmaceuticals | G15: 1751 | H15: 152 | I15: 2183.59 | J15: 100 | K15: 1655.04 | L15: 3 | M15: Paid
A16: S016 | B16: 2025-04-09 | C16: C003 | D16: E03 | E16: East | F16: Industrial Goods | G16: 1019 | H16: 741 | I16: 6242.19 | J16: 150 | K16: 4165.58 | L16: 5 | M16: Pending
A17: S017 | B17: 18/02/2025 | C17: C009 | D17: E03 | E17: east | F17: Electronics | G17: 1226 | H17: 69 | I17: 1519.91 | J17: 100 | K17: 1212.33 | L17: 4 | M17: Pending
A18: S018 | B18: 02-12-2025 | C18: C005 | D18: E02 | E18: south | F18: Industrial Goods | G18: 989 | H18: 62 | I18: 1063.85 | J18: 100 | K18: 689.81 | L18: 1 | M18: Paid
A19: S019 | B19: 2025-03-02 | C19: C003 | D19: E01 | E19: north | F19: Pharmaceuticals | G19: 1320 | H19: 373 | I19: 3639.6 | J19: 150 | K19: 2777.43 | L19: 3 | M19: Overdue
A20: S020 | B20: 02-21-2025 | C20: C004 | D20: E04 | E20: North | F20: Food Products | G20: 1377 | H20: 90 | I20: 1446.57 | J20: 0 | K20: 1108.86 | L20: 8 | M20: Overdue
A21: S021 | B21: 11/01/2025 | C21: C003 | D21: E03 | E21: East | F21: Pharmaceuticals | G21: 1418 | H21: 82 | I21: 1538.72 | J21: 0 | K21: 1205.88 | L21: 3 | M21: Overdue
A22: S022 | B22: 2025-05-01 | C22: C005 | D22: E03 | E22: East | F22: Medical Equipment | G22: 419 | H22: 731 | I22: 6379.12 | J22: 0 | K22: 5303.89 | L22: 4 | M22: Paid
A23: S023 | B23: 2025-01-18 | C23: C006 | D23: E03 | E23: east | F23: Electronics | G23: 614 | H23: 282 | I23: 2171.81 | J23: 50 | K23: 1826.53 | L23: 4 | M23: Paid
A24: S024 | B24: 03-22-2025 | C24: C003 | D24: E01 | E24: South | F24: Food Products | G24: 1312 | H24: 83 | I24: 1154.92 | J24: 100 | K24: 938.59 | L24: 5 | M24: Overdue
A25: S025 | B25: 2025-04-23 | C25: C005 | D25: E02 | E25: East | F25: Electronics | G25: 356 | H25: 732 | I25: 5175.49 | J25: 50 | K25: 3640.79 | L25: 2 | M25: Overdue
A26: S026 | B26: 19/01/2025 | C26: C004 | D26: E01 | E26: East | F26: Electronics | G26: 972 | H26: 782 | I26: 7379.59 | J26: 0 | K26: 4749.58 | L26: 7 | M26: Paid
A27: S027 | B27: 2025-01-27 | C27: C006 | D27: E05 | E27: East | F27: Medical Equipment | G27: 1554 | H27: 681 | I27: 6721.7 | J27: 50 | K27: 4941.06 | L27: 7 | M27: Paid
A28: S028 | B28: 02-01-2025 | C28: C006 | D28: E01 | E28: West | F28: Food Products | G28: 573 | H28: 800 | I28: 5870.23 | J28: 0 | K28: 3823.25 | L28: 1 | M28: Paid
A29: S029 | B29: 2025-01-09 | C29: C008 | D29: E03 | E29: east | F29: Medical Equipment | G29: 869 | H29: 395 | I29: 2960.14 | J29: 100 | K29: 1874 | L29: 7 | M29: Paid
A30: S030 | B30: 03-17-2025 | C30: C004 | D30: E02 | E30: North | F30: Electronics | G30: 1373 | H30: 503 | I30: 4897.32 | J30: 50 | K30: 3268.35 | L30: 7 | M30: Overdue
A31: S031 | B31: 2025-01-24 | C31: C002 | D31: E05 | E31: north | F31: Industrial Goods | G31: 134 | H31: 100 | I31: 779.31 | J31: 0 | K31: 612.28 | L31: 8 | M31: Paid
A32: S032 | B32: 2025-04-27 | C32: C007 | D32: E04 | E32: east | F32: Industrial Goods | G32: 298 | H32: 732 | I32: 6203.82 | J32: 50 | K32: 4240.52 | L32: 1 | M32: Pending
A33: S033 | B33: 2025-02-18 | C33: C009 | D33: E02 | E33: North | F33: Medical Equipment | G33: 914 | H33: 581 | I33: 5211.6 | J33: 100 | K33: 3689.03 | L33: 6 | M33: Paid
A34: S034 | B34: 04-05-2025 | C34: C001 | D34: E04 | E34: East | F34: Food Products | G34: 1787 | H34: 579 | I34: 4363.21 | J34: 150 | K34: 2661.05 | L34: 7 | M34: Pending
A35: S035 | B35: 06/03/2025 | C35: C007 | D35: E02 | E35: north | F35: Medical Equipment | G35: 1869 | H35: 713 | I35: 5693.32 | J35: 50 | K35: 3860.61 | L35: 2 | M35: Pending
A36: S036 | B36: 01-11-2025 | C36: C003 | D36: E04 | E36: north | F36: Food Products | G36: 582 | H36: 713 | I36: 6379.35 | J36: 100 | K36: 5176.56 | L36: 6 | M36: Overdue
A37: S037 | B37: 26/04/2025 | C37: C008 | D37: E02 | E37: East | F37: Pharmaceuticals | G37: 1797 | H37: 101 | I37: 2024.6 | J37: 50 | K37: 1659.29 | L37: 7 | M37: Paid
A38: S038 | B38: 23/04/2025 | C38: C005 | D38: E03 | E38: East | F38: Medical Equipment | G38: 1531 | H38: 367 | I38: 3455.27 | J38: 50 | K38: 2419.52 | L38: 1 | M38: Overdue
A39: S039 | B39: 26/02/2025 | C39: C003 | D39: E05 | E39: North | F39: Electronics | G39: 1151 | H39: 274 | I39: 2401.56 | J39: 150 | K39: 1658.08 | L39: 6 | M39: Overdue
A40: S040 | B40: 2025-04-17 | C40: C002 | D40: E05 | E40: east | F40: Industrial Goods | G40: 1739 | H40: 105 | I40: 1436.82 | J40: 50 | K40: 967.56 | L40: 1 | M40: Paid
...

Sheet  Cleaned Data Shipments
A1: ShipmentID | B1: ShipDate | C1: CustomerID | D1: EmployeeID | E1: Region | F1: ProductCategory | G1: DistanceKM | H1: WeightKG | I1: ShippingFee | J1: Discount | K1: NetRevenue | L1: Cost | M1: Profit | N1: Profit Margin | O1: Revenue per KM | P1: SHIPEMENT CATEGORY | Q1: DeliveryDays | R1: PaymentStatus | S1: Delivery status | T1: payement risk flag | U1: ProductCategories | V1: EmployeeName | W1: HandlingstPerKG
A2: S001 | B2: 46095 | C2: C008 | D2: E04 | E2: North | F2: Industrial Goods | G2: 1607 | H2: 421 | I2: 4125.16 | J2: 100 | K2: =I2-J2 -> 4025.16 | L2: 2508.64 | M2: =K2-L2 -> 1516.52 | N2: =M2/K2 -> 0.37676018 | O2: =K2/G2 -> 2.5047666 | P2: =IF(M2>=2000,"HIGH",IF(M2>=1000,"MEDIUM","LOW")) -> MEDIUM | Q2: 8 | R2: Paid | S2: =IF(Q2<=3,"Fast", IF(Q2<=5,"Normal","Delayed")) -> Delayed | T2: =IF(OR(R2="Pending",R2="Overdue"),"Risk","Clear") -> Clear | U2: =_xlfn.XLOOKUP(C2,Customers!$A$1:$A$11,Customers!$B$1:$B$11) -> Sun Pharmaceutical Industries | V2: =_xlfn.XLOOKUP(D2,Employees!$A$1:$A$6,Employees!$B$1:$B$6) -> Neha Verma | W2: =_xlfn.XLOOKUP(F2,Categories!$A$1:$A$6,Categories!$C$1:$C$6) -> 3 | AA2: TOTAL REVENUE | AC2: =SUBTOTAL(9,K2:K301) -> 1060251.7
A3: S002 | B3: 45812 | C3: C005 | D3: E04 | E3: West | F3: Medical Equipment | G3: 977 | H3: 475 | I3: 3650.61 | J3: 0 | K3: =I3-J3 -> 3650.61 | L3: 2887.46 | M3: =K3-L3 -> 763.15 | N3: =M3/K3 -> 0.20904726 | O3: =K3/G3 -> 3.7365507 | P3: =IF(M3>=2000,"HIGH",IF(M3>=1000,"MEDIUM","LOW")) -> LOW | Q3: 1 | R3: Pending | S3: =IF(Q3<=3,"Fast", IF(Q3<=5,"Normal","Delayed")) -> Fast | T3: =IF(OR(R3="Pending",R3="Overdue"),"Risk","Clear") -> Risk | U3: =_xlfn.XLOOKUP(C3,Customers!$A$1:$A$11,Customers!$B$1:$B$11) -> Flipkart Internet Pvt Ltd | V3: =_xlfn.XLOOKUP(D3,Employees!$A$1:$A$6,Employees!$B$1:$B$6) -> Neha Verma | W3: =_xlfn.XLOOKUP(F3,Categories!$A$1:$A$6,Categories!$C$1:$C$6) -> 2
A4: S003 | B4: 45672 | C4: C006 | D4: E02 | E4: West | F4: Industrial Goods | G4: 541 | H4: 178 | I4: 1786.34 | J4: 50 | K4: =I4-J4 -> 1736.34 | L4: 1176.14 | M4: =K4-L4 -> 560.2 | N4: =M4/K4 -> 0.32263266 | O4: =K4/G4 -> 3.2095009 | P4: =IF(M4>=2000,"HIGH",IF(M4>=1000,"MEDIUM","LOW")) -> LOW | Q4: 7 | R4: Paid | S4: =IF(Q4<=3,"Fast", IF(Q4<=5,"Normal","Delayed")) -> Delayed | T4: =IF(OR(R4="Pending",R4="Overdue"),"Risk","Clear") -> Clear | U4: =_xlfn.XLOOKUP(C4,Customers!$A$1:$A$11,Customers!$B$1:$B$11) -> Amazon Seller Services Pvt Ltd | V4: =_xlfn.XLOOKUP(D4,Employees!$A$1:$A$6,Employees!$B$1:$B$6) -> Priya Sharma | W4: =_xlfn.XLOOKUP(F4,Categories!$A$1:$A$6,Categories!$C$1:$C$6) -> 3 | AA4: TOTAL PROFIT | AC4: =SUBTOTAL(9,M2:M301) -> 264031.74
A5: S005 | B5: 45719 | C5: C010 | D5: E03 | E5: West | F5: Medical Equipment | G5: 722 | H5: 164 | I5: 1842.12 | J5: 100 | K5: =I5-J5 -> 1742.12 | L5: 1320.36 | M5: =K5-L5 -> 421.76 | N5: =M5/K5 -> 0.24209584 | O5: =K5/G5 -> 2.4129086 | P5: =IF(M5>=2000,"HIGH",IF(M5>=1000,"MEDIUM","LOW")) -> LOW | Q5: 3 | R5: Overdue | S5: =IF(Q5<=3,"Fast", IF(Q5<=5,"Normal","Delayed")) -> Fast | T5: =IF(OR(R5="Pending",R5="Overdue"),"Risk","Clear") -> Risk | U5: =_xlfn.XLOOKUP(C5,Customers!$A$1:$A$11,Customers!$B$1:$B$11) -> BigBasket Retail Pvt Ltd | V5: =_xlfn.XLOOKUP(D5,Employees!$A$1:$A$6,Employees!$B$1:$B$6) -> Amit Kulkarni | W5: =_xlfn.XLOOKUP(F5,Categories!$A$1:$A$6,Categories!$C$1:$C$6) -> 2
A6: S006 | B6: 45715 | C6: C010 | D6: E01 | E6: South | F6: Pharmaceuticals | G6: 875 | H6: 314 | I6: 2382.2 | J6: 150 | K6: =I6-J6 -> 2232.2 | L6: 1540.1 | M6: =K6-L6 -> 692.1 | N6: =M6/K6 -> 0.31005286 | O6: =K6/G6 -> 2.5510857 | P6: =IF(M6>=2000,"HIGH",IF(M6>=1000,"MEDIUM","LOW")) -> LOW | Q6: 2 | R6: Overdue | S6: =IF(Q6<=3,"Fast", IF(Q6<=5,"Normal","Delayed")) -> Fast | T6: =IF(OR(R6="Pending",R6="Overdue"),"Risk","Clear") -> Risk | U6: =_xlfn.XLOOKUP(C6,Customers!$A$1:$A$11,Customers!$B$1:$B$11) -> BigBasket Retail Pvt Ltd | V6: =_xlfn.XLOOKUP(D6,Employees!$A$1:$A$6,Employees!$B$1:$B$6) -> Rahul Mehta | W6: =_xlfn.XLOOKUP(F6,Categories!$A$1:$A$6,Categories!$C$1:$C$6) -> 2 | AA6: Average Delivery Time | AC6: =SUBTOTAL(1,Q2:Q301) -> 4.4533333
A7: S007 | B7: 45781 | C7: C005 | D7: E02 | E7: North | F7: Food Products | G7: 362 | H7: 772 | I7: 5185.91 | J7: 0 | K7: =I7-J7 -> 5185.91 | L7: 4314.46 | M7: =K7-L7 -> 871.45 | N7: =M7/K7 -> 0.16804187 | O7: =K7/G7 -> 14.325718 | P7: =IF(M7>=2000,"HIGH",IF(M7>=1000,"MEDIUM","LOW")) -> LOW | Q7: 8 | R7: Pending | S7: =IF(Q7<=3,"Fast", IF(Q7<=5,"Normal","Delayed")) -> Delayed | T7: =IF(OR(R7="Pending",R7="Overdue"),"Risk","Clear") -> Risk | U7: =_xlfn.XLOOKUP(C7,Customers!$A$1:$A$11,Customers!$B$1:$B$11) -> Flipkart Internet Pvt Ltd | V7: =_xlfn.XLOOKUP(D7,Employees!$A$1:$A$6,Employees!$B$1:$B$6) -> Priya Sharma | W7: =_xlfn.XLOOKUP(F7,Categories!$A$1:$A$6,Categories!$C$1:$C$6) -> 1.5
A8: S008 | B8: 45712 | C8: C010 | D8: E03 | E8: East | F8: Food Products | G8: 1261 | H8: 187 | I8: 1900.42 | J8: 0 | K8: =I8-J8 -> 1900.42 | L8: 1536.94 | M8: =K8-L8 -> 363.48 | N8: =M8/K8 -> 0.19126298 | O8: =K8/G8 -> 1.5070738 | P8: =IF(M8>=2000,"HIGH",IF(M8>=1000,"MEDIUM","LOW")) -> LOW | Q8: 6 | R8: Overdue | S8: =IF(Q8<=3,"Fast", IF(Q8<=5,"Normal","Delayed")) -> Delayed | T8: =IF(OR(R8="Pending",R8="Overdue"),"Risk","Clear") -> Risk | U8: =_xlfn.XLOOKUP(C8,Customers!$A$1:$A$11,Customers!$B$1:$B$11) -> BigBasket Retail Pvt Ltd | V8: =_xlfn.XLOOKUP(D8,Employees!$A$1:$A$6,Employees!$B$1:$B$6) -> Amit Kulkarni | W8: =_xlfn.XLOOKUP(F8,Categories!$A$1:$A$6,Categories!$C$1:$C$6) -> 1.5 | AA8: Average Shipment Distance | AC8: =SUBTOTAL(1,G2:G301) -> 1069.7067
A9: S009 | B9: 45763 | C9: C004 | D9: E02 | E9: South | F9: Industrial Goods | G9: 1894 | H9: 607 | I9: 5993.83 | J9: 100 | K9: =I9-J9 -> 5893.83 | L9: 4814.13 | M9: =K9-L9 -> 1079.7 | N9: =M9/K9 -> 0.18319157 | O9: =K9/G9 -> 3.1118427 | P9: =IF(M9>=2000,"HIGH",IF(M9>=1000,"MEDIUM","LOW")) -> MEDIUM | Q9: 5 | R9: Overdue | S9: =IF(Q9<=3,"Fast", IF(Q9<=5,"Normal","Delayed")) -> Normal | T9: =IF(OR(R9="Pending",R9="Overdue"),"Risk","Clear") -> Risk | U9: =_xlfn.XLOOKUP(C9,Customers!$A$1:$A$11,Customers!$B$1:$B$11) -> Fortis Healthcare | V9: =_xlfn.XLOOKUP(D9,Employees!$A$1:$A$6,Employees!$B$1:$B$6) -> Priya Sharma | W9: =_xlfn.XLOOKUP(F9,Categories!$A$1:$A$6,Categories!$C$1:$C$6) -> 3
A10: S010 | B10: 46095 | C10: C001 | D10: E04 | E10: North | F10: Electronics | G10: 429 | H10: 539 | I10: 4056 | J10: 100 | K10: =I10-J10 -> 3956 | L10: 3129.93 | M10: =K10-L10 -> 826.07 | N10: =M10/K10 -> 0.20881446 | O10: =K10/G10 -> 9.2214452 | P10: =IF(M10>=2000,"HIGH",IF(M10>=1000,"MEDIUM","LOW")) -> LOW | Q10: 4 | R10: Pending | S10: =IF(Q10<=3,"Fast", IF(Q10<=5,"Normal","Delayed")) -> Normal | T10: =IF(OR(R10="Pending",R10="Overdue"),"Risk","Clear") -> Risk | U10: =_xlfn.XLOOKUP(C10,Customers!$A$1:$A$11,Customers!$B$1:$B$11) -> Apollo Hospitals | V10: =_xlfn.XLOOKUP(D10,Employees!$A$1:$A$6,Employees!$B$1:$B$6) -> Neha Verma | W10: =_xlfn.XLOOKUP(F10,Categories!$A$1:$A$6,Categories!$C$1:$C$6) -> 2.5 | AA10: Total Number of Shipments | AC10: =COUNTA(A2:A301) -> 300
A11: S011 | B11: 45701 | C11: C005 | D11: E01 | E11: East | F11: Electronics | G11: 1327 | H11: 386 | I11: 3651.63 | J11: 150 | K11: =I11-J11 -> 3501.63 | L11: 3008.95 | M11: =K11-L11 -> 492.68 | N11: =M11/K11 -> 0.14070019 | O11: =K11/G11 -> 2.6387566 | P11: =IF(M11>=2000,"HIGH",IF(M11>=1000,"MEDIUM","LOW")) -> LOW | Q11: 7 | R11: Pending | S11: =IF(Q11<=3,"Fast", IF(Q11<=5,"Normal","Delayed")) -> Delayed | T11: =IF(OR(R11="Pending",R11="Overdue"),"Risk","Clear") -> Risk | U11: =_xlfn.XLOOKUP(C11,Customers!$A$1:$A$11,Customers!$B$1:$B$11) -> Flipkart Internet Pvt Ltd | V11: =_xlfn.XLOOKUP(D11,Employees!$A$1:$A$6,Employees!$B$1:$B$6) -> Rahul Mehta | W11: =_xlfn.XLOOKUP(F11,Categories!$A$1:$A$6,Categories!$C$1:$C$6) -> 2.5
A12: S012 | B12: 45678 | C12: C001 | D12: E02 | E12: South | F12: Medical Equipment | G12: 575 | H12: 207 | I12: 1856.45 | J12: 0 | K12: =I12-J12 -> 1856.45 | L12: 1229.75 | M12: =K12-L12 -> 626.7 | N12: =M12/K12 -> 0.33757979 | O12: =K12/G12 -> 3.2286087 | P12: =IF(M12>=2000,"HIGH",IF(M12>=1000,"MEDIUM","LOW")) -> LOW | Q12: 7 | R12: Overdue | S12: =IF(Q12<=3,"Fast", IF(Q12<=5,"Normal","Delayed")) -> Delayed | T12: =IF(OR(R12="Pending",R12="Overdue"),"Risk","Clear") -> Risk | U12: =_xlfn.XLOOKUP(C12,Customers!$A$1:$A$11,Customers!$B$1:$B$11) -> Apollo Hospitals | V12: =_xlfn.XLOOKUP(D12,Employees!$A$1:$A$6,Employees!$B$1:$B$6) -> Priya Sharma | W12: =_xlfn.XLOOKUP(F12,Categories!$A$1:$A$6,Categories!$C$1:$C$6) -> 2 | AA12: west region revenue | AC12: =SUMIF(E2:E301,"West",K2:K301) -> 221311.07
A13: S013 | B13: 46095 | C13: C008 | D13: E02 | E13: West | F13: Industrial Goods | G13: 710 | H13: 148 | I13: 1716.99 | J13: 50 | K13: =I13-J13 -> 1666.99 | L13: 1178.48 | M13: =K13-L13 -> 488.51 | N13: =M13/K13 -> 0.29304915 | O13: =K13/G13 -> 2.3478732 | P13: =IF(M13>=2000,"HIGH",IF(M13>=1000,"MEDIUM","LOW")) -> LOW | Q13: 6 | R13: Pending | S13: =IF(Q13<=3,"Fast", IF(Q13<=5,"Normal","Delayed")) -> Delayed | T13: =IF(OR(R13="Pending",R13="Overdue"),"Risk","Clear") -> Risk | U13: =_xlfn.XLOOKUP(C13,Customers!$A$1:$A$11,Customers!$B$1:$B$11) -> Sun Pharmaceutical Industries | V13: =_xlfn.XLOOKUP(D13,Employees!$A$1:$A$6,Employees!$B$1:$B$6) -> Priya Sharma | W13: =_xlfn.XLOOKUP(F13,Categories!$A$1:$A$6,Categories!$C$1:$C$6) -> 3
A14: S014 | B14: 45719 | C14: C003 | D14: E01 | E14: East | F14: Electronics | G14: 401 | H14: 176 | I14: 1350.24 | J14: 50 | K14: =I14-J14 -> 1300.24 | L14: 894.87 | M14: =K14-L14 -> 405.37 | N14: =M14/K14 -> 0.31176552 | O14: =K14/G14 -> 3.2424938 | P14: =IF(M14>=2000,"HIGH",IF(M14>=1000,"MEDIUM","LOW")) -> LOW | Q14: 3 | R14: Pending | S14: =IF(Q14<=3,"Fast", IF(Q14<=5,"Normal","Delayed")) -> Fast | T14: =IF(OR(R14="Pending",R14="Overdue"),"Risk","Clear") -> Risk | U14: =_xlfn.XLOOKUP(C14,Customers!$A$1:$A$11,Customers!$B$1:$B$11) -> Tata Steel Limited | V14: =_xlfn.XLOOKUP(D14,Employees!$A$1:$A$6,Employees!$B$1:$B$6) -> Rahul Mehta | W14: =_xlfn.XLOOKUP(F14,Categories!$A$1:$A$6,Categories!$C$1:$C$6) -> 2.5 | AA14: Electronics shipments. | AC14: =SUMIF(F2:F301,"Electronics",M2:M301) -> 54664.15
A15: S015 | B15: 45725 | C15: C003 | D15: E03 | E15: North | F15: Pharmaceuticals | G15: 1751 | H15: 152 | I15: 2183.59 | J15: 100 | K15: =I15-J15 -> 2083.59 | L15: 1655.04 | M15: =K15-L15 -> 428.55 | N15: =M15/K15 -> 0.20567866 | O15: =K15/G15 -> 1.1899429 | P15: =IF(M15>=2000,"HIGH",IF(M15>=1000,"MEDIUM","LOW")) -> LOW | Q15: 3 | R15: Paid | S15: =IF(Q15<=3,"Fast", IF(Q15<=5,"Normal","Delayed")) -> Fast | T15: =IF(OR(R15="Pending",R15="Overdue"),"Risk","Clear") -> Clear | U15: =_xlfn.XLOOKUP(C15,Customers!$A$1:$A$11,Customers!$B$1:$B$11) -> Tata Steel Limited | V15: =_xlfn.XLOOKUP(D15,Employees!$A$1:$A$6,Employees!$B$1:$B$6) -> Amit Kulkarni | W15: =_xlfn.XLOOKUP(F15,Categories!$A$1:$A$6,Categories!$C$1:$C$6) -> 2
A16: S016 | B16: 45756 | C16: C003 | D16: E03 | E16: East | F16: Industrial Goods | G16: 1019 | H16: 741 | I16: 6242.19 | J16: 150 | K16: =I16-J16 -> 6092.19 | L16: 4165.58 | M16: =K16-L16 -> 1926.61 | N16: =M16/K16 -> 0.3162426 | O16: =K16/G16 -> 5.9785967 | P16: =IF(M16>=2000,"HIGH",IF(M16>=1000,"MEDIUM","LOW")) -> MEDIUM | Q16: 5 | R16: Pending | S16: =IF(Q16<=3,"Fast", IF(Q16<=5,"Normal","Delayed")) -> Normal | T16: =IF(OR(R16="Pending",R16="Overdue"),"Risk","Clear") -> Risk | U16: =_xlfn.XLOOKUP(C16,Customers!$A$1:$A$11,Customers!$B$1:$B$11) -> Tata Steel Limited | V16: =_xlfn.XLOOKUP(D16,Employees!$A$1:$A$6,Employees!$B$1:$B$6) -> Amit Kulkarni | W16: =_xlfn.XLOOKUP(F16,Categories!$A$1:$A$6,Categories!$C$1:$C$6) -> 3 | AA16: Count shipments | AC16: =COUNTIF(Q2:Q301,">5") -> 114
A17: S017 | B17: 45706 | C17: C009 | D17: E03 | E17: East | F17: Electronics | G17: 1226 | H17: 69 | I17: 1519.91 | J17: 100 | K17: =I17-J17 -> 1419.91 | L17: 1212.33 | M17: =K17-L17 -> 207.58 | N17: =M17/K17 -> 0.14619236 | O17: =K17/G17 -> 1.1581648 | P17: =IF(M17>=2000,"HIGH",IF(M17>=1000,"MEDIUM","LOW")) -> LOW | Q17: 4 | R17: Pending | S17: =IF(Q17<=3,"Fast", IF(Q17<=5,"Normal","Delayed")) -> Normal | T17: =IF(OR(R17="Pending",R17="Overdue"),"Risk","Clear") -> Risk | U17: =_xlfn.XLOOKUP(C17,Customers!$A$1:$A$11,Customers!$B$1:$B$11) -> Lupin Pharmaceuticals | V17: =_xlfn.XLOOKUP(D17,Employees!$A$1:$A$6,Employees!$B$1:$B$6) -> Amit Kulkarni | W17: =_xlfn.XLOOKUP(F17,Categories!$A$1:$A$6,Categories!$C$1:$C$6) -> 2.5 | AG17: Region | AH17: ProductCategory
A18: S018 | B18: 45993 | C18: C005 | D18: E02 | E18: South | F18: Industrial Goods | G18: 989 | H18: 62 | I18: 1063.85 | J18: 100 | K18: =I18-J18 -> 963.85 | L18: 689.81 | M18: =K18-L18 -> 274.04 | N18: =M18/K18 -> 0.2843181 | O18: =K18/G18 -> 0.97457027 | P18: =IF(M18>=2000,"HIGH",IF(M18>=1000,"MEDIUM","LOW")) -> LOW | Q18: 1 | R18: Paid | S18: =IF(Q18<=3,"Fast", IF(Q18<=5,"Normal","Delayed")) -> Fast | T18: =IF(OR(R18="Pending",R18="Overdue"),"Risk","Clear") -> Clear | U18: =_xlfn.XLOOKUP(C18,Customers!$A$1:$A$11,Customers!$B$1:$B$11) -> Flipkart Internet Pvt Ltd | V18: =_xlfn.XLOOKUP(D18,Employees!$A$1:$A$6,Employees!$B$1:$B$6) -> Priya Sharma | W18: =_xlfn.XLOOKUP(F18,Categories!$A$1:$A$6,Categories!$C$1:$C$6) -> 3 | AA18: Average profit for Pharmaceutical shipments in South region. | AC18: =DAVERAGE(A1:V301,M1,AG17:AI18) -> 849.53412 | AG18: South | AH18: Pharmaceuticals
A19: S019 | B19: 45718 | C19: C003 | D19: E01 | E19: North | F19: Pharmaceuticals | G19: 1320 | H19: 373 | I19: 3639.6 | J19: 150 | K19: =I19-J19 -> 3489.6 | L19: 2777.43 | M19: =K19-L19 -> 712.17 | N19: =M19/K19 -> 0.20408356 | O19: =K19/G19 -> 2.6436364 | P19: =IF(M19>=2000,"HIGH",IF(M19>=1000,"MEDIUM","LOW")) -> LOW | Q19: 3 | R19: Overdue | S19: =IF(Q19<=3,"Fast", IF(Q19<=5,"Normal","Delayed")) -> Fast | T19: =IF(OR(R19="Pending",R19="Overdue"),"Risk","Clear") -> Risk | U19: =_xlfn.XLOOKUP(C19,Customers!$A$1:$A$11,Customers!$B$1:$B$11) -> Tata Steel Limited | V19: =_xlfn.XLOOKUP(D19,Employees!$A$1:$A$6,Employees!$B$1:$B$6) -> Rahul Mehta | W19: =_xlfn.XLOOKUP(F19,Categories!$A$1:$A$6,Categories!$C$1:$C$6) -> 2
A20: S020 | B20: 46095 | C20: C004 | D20: E04 | E20: North | F20: Food Products | G20: 1377 | H20: 90 | I20: 1446.57 | J20: 0 | K20: =I20-J20 -> 1446.57 | L20: 1108.86 | M20: =K20-L20 -> 337.71 | N20: =M20/K20 -> 0.23345569 | O20: =K20/G20 -> 1.0505229 | P20: =IF(M20>=2000,"HIGH",IF(M20>=1000,"MEDIUM","LOW")) -> LOW | Q20: 8 | R20: Overdue | S20: =IF(Q20<=3,"Fast", IF(Q20<=5,"Normal","Delayed")) -> Delayed | T20: =IF(OR(R20="Pending",R20="Overdue"),"Risk","Clear") -> Risk | U20: =_xlfn.XLOOKUP(C20,Customers!$A$1:$A$11,Customers!$B$1:$B$11) -> Fortis Healthcare | V20: =_xlfn.XLOOKUP(D20,Employees!$A$1:$A$6,Employees!$B$1:$B$6) -> Neha Verma | W20: =_xlfn.XLOOKUP(F20,Categories!$A$1:$A$6,Categories!$C$1:$C$6) -> 1.5
A21: S021 | B21: 45668 | C21: C003 | D21: E03 | E21: East | F21: Pharmaceuticals | G21: 1418 | H21: 82 | I21: 1538.72 | J21: 0 | K21: =I21-J21 -> 1538.72 | L21: 1205.88 | M21: =K21-L21 -> 332.84 | N21: =M21/K21 -> 0.21630966 | O21: =K21/G21 -> 1.085134 | P21: =IF(M21>=2000,"HIGH",IF(M21>=1000,"MEDIUM","LOW")) -> LOW | Q21: 3 | R21: Overdue | S21: =IF(Q21<=3,"Fast", IF(Q21<=5,"Normal","Delayed")) -> Fast | T21: =IF(OR(R21="Pending",R21="Overdue"),"Risk","Clear") -> Risk | U21: =_xlfn.XLOOKUP(C21,Customers!$A$1:$A$11,Customers!$B$1:$B$11) -> Tata Steel Limited | V21: =_xlfn.XLOOKUP(D21,Employees!$A$1:$A$6,Employees!$B$1:$B$6) -> Amit Kulkarni | W21: =_xlfn.XLOOKUP(F21,Categories!$A$1:$A$6,Categories!$C$1:$C$6) -> 2
A22: S022 | B22: 45778 | C22: C005 | D22: E03 | E22: East | F22: Medical Equipment | G22: 419 | H22: 731 | I22: 6379.12 | J22: 0 | K22: =I22-J22 -> 6379.12 | L22: 5303.89 | M22: =K22-L22 -> 1075.23 | N22: =M22/K22 -> 0.1685546 | O22: =K22/G22 -> 15.22463 | P22: =IF(M22>=2000,"HIGH",IF(M22>=1000,"MEDIUM","LOW")) -> MEDIUM | Q22: 4 | R22: Paid | S22: =IF(Q22<=3,"Fast", IF(Q22<=5,"Normal","Delayed")) -> Normal | T22: =IF(OR(R22="Pending",R22="Overdue"),"Risk","Clear") -> Clear | U22: =_xlfn.XLOOKUP(C22,Customers!$A$1:$A$11,Customers!$B$1:$B$11) -> Flipkart Internet Pvt Ltd | V22: =_xlfn.XLOOKUP(D22,Employees!$A$1:$A$6,Employees!$B$1:$B$6) -> Amit Kulkarni | W22: =_xlfn.XLOOKUP(F22,Categories!$A$1:$A$6,Categories!$C$1:$C$6) -> 2
A23: S023 | B23: 45675 | C23: C006 | D23: E03 | E23: East | F23: Electronics | G23: 614 | H23: 282 | I23: 2171.81 | J23: 50 | K23: =I23-J23 -> 2121.81 | L23: 1826.53 | M23: =K23-L23 -> 295.28 | N23: =M23/K23 -> 0.1391642 | O23: =K23/G23 -> 3.4557166 | P23: =IF(M23>=2000,"HIGH",IF(M23>=1000,"MEDIUM","LOW")) -> LOW | Q23: 4 | R23: Paid | S23: =IF(Q23<=3,"Fast", IF(Q23<=5,"Normal","Delayed")) -> Normal | T23: =IF(OR(R23="Pending",R23="Overdue"),"Risk","Clear") -> Clear | U23: =_xlfn.XLOOKUP(C23,Customers!$A$1:$A$11,Customers!$B$1:$B$11) -> Amazon Seller Services Pvt Ltd | V23: =_xlfn.XLOOKUP(D23,Employees!$A$1:$A$6,Employees!$B$1:$B$6) -> Amit Kulkarni | W23: =_xlfn.XLOOKUP(F23,Categories!$A$1:$A$6,Categories!$C$1:$C$6) -> 2.5
A24: S024 | B24: 46095 | C24: C003 | D24: E01 | E24: South | F24: Food Products | G24: 1312 | H24: 83 | I24: 1154.92 | J24: 100 | K24: =I24-J24 -> 1054.92 | L24: 938.59 | M24: =K24-L24 -> 116.33 | N24: =M24/K24 -> 0.11027376 | O24: =K24/G24 -> 0.80405488 | P24: =IF(M24>=2000,"HIGH",IF(M24>=1000,"MEDIUM","LOW")) -> LOW | Q24: 5 | R24: Overdue | S24: =IF(Q24<=3,"Fast", IF(Q24<=5,"Normal","Delayed")) -> Normal | T24: =IF(OR(R24="Pending",R24="Overdue"),"Risk","Clear") -> Risk | U24: =_xlfn.XLOOKUP(C24,Customers!$A$1:$A$11,Customers!$B$1:$B$11) -> Tata Steel Limited | V24: =_xlfn.XLOOKUP(D24,Employees!$A$1:$A$6,Employees!$B$1:$B$6) -> Rahul Mehta | W24: =_xlfn.XLOOKUP(F24,Categories!$A$1:$A$6,Categories!$C$1:$C$6) -> 1.5
A25: S025 | B25: 45770 | C25: C005 | D25: E02 | E25: East | F25: Electronics | G25: 356 | H25: 732 | I25: 5175.49 | J25: 50 | K25: =I25-J25 -> 5125.49 | L25: 3640.79 | M25: =K25-L25 -> 1484.7 | N25: =M25/K25 -> 0.28966987 | O25: =K25/G25 -> 14.397444 | P25: =IF(M25>=2000,"HIGH",IF(M25>=1000,"MEDIUM","LOW")) -> MEDIUM | Q25: 2 | R25: Overdue | S25: =IF(Q25<=3,"Fast", IF(Q25<=5,"Normal","Delayed")) -> Fast | T25: =IF(OR(R25="Pending",R25="Overdue"),"Risk","Clear") -> Risk | U25: =_xlfn.XLOOKUP(C25,Customers!$A$1:$A$11,Customers!$B$1:$B$11) -> Flipkart Internet Pvt Ltd | V25: =_xlfn.XLOOKUP(D25,Employees!$A$1:$A$6,Employees!$B$1:$B$6) -> Priya Sharma | W25: =_xlfn.XLOOKUP(F25,Categories!$A$1:$A$6,Categories!$C$1:$C$6) -> 2.5
A26: S026 | B26: 45676 | C26: C004 | D26: E01 | E26: East | F26: Electronics | G26: 972 | H26: 782 | I26: 7379.59 | J26: 0 | K26: =I26-J26 -> 7379.59 | L26: 4749.58 | M26: =K26-L26 -> 2630.01 | N26: =M26/K26 -> 0.35638972 | O26: =K26/G26 -> 7.5921708 | P26: =IF(M26>=2000,"HIGH",IF(M26>=1000,"MEDIUM","LOW")) -> HIGH | Q26: 7 | R26: Paid | S26: =IF(Q26<=3,"Fast", IF(Q26<=5,"Normal","Delayed")) -> Delayed | T26: =IF(OR(R26="Pending",R26="Overdue"),"Risk","Clear") -> Clear | U26: =_xlfn.XLOOKUP(C26,Customers!$A$1:$A$11,Customers!$B$1:$B$11) -> Fortis Healthcare | V26: =_xlfn.XLOOKUP(D26,Employees!$A$1:$A$6,Employees!$B$1:$B$6) -> Rahul Mehta | W26: =_xlfn.XLOOKUP(F26,Categories!$A$1:$A$6,Categories!$C$1:$C$6) -> 2.5
A27: S027 | B27: 45684 | C27: C006 | D27: E05 | E27: East | F27: Medical Equipment | G27: 1554 | H27: 681 | I27: 6721.7 | J27: 50 | K27: =I27-J27 -> 6671.7 | L27: 4941.06 | M27: =K27-L27 -> 1730.64 | N27: =M27/K27 -> 0.25940015 | O27: =K27/G27 -> 4.2932432 | P27: =IF(M27>=2000,"HIGH",IF(M27>=1000,"MEDIUM","LOW")) -> MEDIUM | Q27: 7 | R27: Paid | S27: =IF(Q27<=3,"Fast", IF(Q27<=5,"Normal","Delayed")) -> Delayed | T27: =IF(OR(R27="Pending",R27="Overdue"),"Risk","Clear") -> Clear | U27: =_xlfn.XLOOKUP(C27,Customers!$A$1:$A$11,Customers!$B$1:$B$11) -> Amazon Seller Services Pvt Ltd | V27: =_xlfn.XLOOKUP(D27,Employees!$A$1:$A$6,Employees!$B$1:$B$6) -> Arjun Patel | W27: =_xlfn.XLOOKUP(F27,Categories!$A$1:$A$6,Categories!$C$1:$C$6) -> 2
A28: S028 | B28: 45659 | C28: C006 | D28: E01 | E28: West | F28: Food Products | G28: 573 | H28: 800 | I28: 5870.23 | J28: 0 | K28: =I28-J28 -> 5870.23 | L28: 3823.25 | M28: =K28-L28 -> 2046.98 | N28: =M28/K28 -> 0.34870525 | O28: =K28/G28 -> 10.244729 | P28: =IF(M28>=2000,"HIGH",IF(M28>=1000,"MEDIUM","LOW")) -> HIGH | Q28: 1 | R28: Paid | S28: =IF(Q28<=3,"Fast", IF(Q28<=5,"Normal","Delayed")) -> Fast | T28: =IF(OR(R28="Pending",R28="Overdue"),"Risk","Clear") -> Clear | U28: =_xlfn.XLOOKUP(C28,Customers!$A$1:$A$11,Customers!$B$1:$B$11) -> Amazon Seller Services Pvt Ltd | V28: =_xlfn.XLOOKUP(D28,Employees!$A$1:$A$6,Employees!$B$1:$B$6) -> Rahul Mehta | W28: =_xlfn.XLOOKUP(F28,Categories!$A$1:$A$6,Categories!$C$1:$C$6) -> 1.5
A29: S029 | B29: 45666 | C29: C008 | D29: E03 | E29: East | F29: Medical Equipment | G29: 869 | H29: 395 | I29: 2960.14 | J29: 100 | K29: =I29-J29 -> 2860.14 | L29: 1874 | M29: =K29-L29 -> 986.14 | N29: =M29/K29 -> 0.34478732 | O29: =K29/G29 -> 3.2913003 | P29: =IF(M29>=2000,"HIGH",IF(M29>=1000,"MEDIUM","LOW")) -> LOW | Q29: 7 | R29: Paid | S29: =IF(Q29<=3,"Fast", IF(Q29<=5,"Normal","Delayed")) -> Delayed | T29: =IF(OR(R29="Pending",R29="Overdue"),"Risk","Clear") -> Clear | U29: =_xlfn.XLOOKUP(C29,Customers!$A$1:$A$11,Customers!$B$1:$B$11) -> Sun Pharmaceutical Industries | V29: =_xlfn.XLOOKUP(D29,Employees!$A$1:$A$6,Employees!$B$1:$B$6) -> Amit Kulkarni | W29: =_xlfn.XLOOKUP(F29,Categories!$A$1:$A$6,Categories!$C$1:$C$6) -> 2
A30: S030 | B30: 46095 | C30: C004 | D30: E02 | E30: North | F30: Electronics | G30: 1373 | H30: 503 | I30: 4897.32 | J30: 50 | K30: =I30-J30 -> 4847.32 | L30: 3268.35 | M30: =K30-L30 -> 1578.97 | N30: =M30/K30 -> 0.32574082 | O30: =K30/G30 -> 3.5304588 | P30: =IF(M30>=2000,"HIGH",IF(M30>=1000,"MEDIUM","LOW")) -> MEDIUM | Q30: 7 | R30: Overdue | S30: =IF(Q30<=3,"Fast", IF(Q30<=5,"Normal","Delayed")) -> Delayed | T30: =IF(OR(R30="Pending",R30="Overdue"),"Risk","Clear") -> Risk | U30: =_xlfn.XLOOKUP(C30,Customers!$A$1:$A$11,Customers!$B$1:$B$11) -> Fortis Healthcare | V30: =_xlfn.XLOOKUP(D30,Employees!$A$1:$A$6,Employees!$B$1:$B$6) -> Priya Sharma | W30: =_xlfn.XLOOKUP(F30,Categories!$A$1:$A$6,Categories!$C$1:$C$6) -> 2.5
... A301: S004 | B301: 45676 | C301: C003 | D301: E04 | E301: North | F301: Industrial Goods | G301: 871 | H301: 713 | I301: 6139.95 | J301: 0 | K301: =I301-J301 -> 6139.95 | L301: 4284.75 | M301: =K301-L301 -> 1855.2 | N301: =M301/K301 -> 0.3021523 | O301: =K301/G301 -> 7.0493111 | P301: =IF(M301>=2000,"HIGH",IF(M301>=1000,"MEDIUM","LOW")) -> MEDIUM | Q301: 1 | R301: Paid | S301: =IF(Q301<=3,"Fast", IF(Q301<=5,"Normal","Delayed")) -> Fast | T301: =IF(OR(R301="Pending",R301="Overdue"),"Risk","Clear") -> Clear | U301: =_xlfn.XLOOKUP(C301,Customers!$A$1:$A$11,Customers!$B$1:$B$11) -> Tata Steel Limited | V301: =_xlfn.XLOOKUP(D301,Employees!$A$1:$A$6,Employees!$B$1:$B$6) -> Neha Verma | W301: =_xlfn.XLOOKUP(F301,Categories!$A$1:$A$6,Categories!$C$1:$C$6) -> 3

Sheet Pivot and Charts
A2: Row Labels | B2: Sum of NetRevenue | D2: Row Labels | E2: Sum of Profit | H2: Row Labels | I2: Count of ShipmentID | L2: Column Labels
A3: West | B3: 221311.07 | D3: Electronics | E3: 54664.15 | H3: 2025 | I3: 239 | L3: Electronics | O3: Food Products | R3: Industrial Goods | U3: Medical Equipment | X3: Pharmaceuticals | AA3: Total Count of ShipmentID | AB3: Total Sum of Profit | AC3: Total Sum of NetRevenue
A4: South | B4: 237896.87 | D4: Food Products | E4: 49692.18 | H4: Qtr1 | I4: 156 | K4: Row Labels | L4: Count of ShipmentID | M4: Sum of Profit | N4: Sum of NetRevenue | O4: Count of ShipmentID | P4: Sum of Profit | Q4: Sum of NetRevenue | R4: Count of ShipmentID | S4: Sum of Profit | T4: Sum of NetRevenue | U4: Count of ShipmentID | V4: Sum of Profit | W4: Sum of NetRevenue | X4: Count of ShipmentID | Y4: Sum of Profit | Z4: Sum of NetRevenue
A5: North | B5: 284709.85 | D5: Industrial Goods | E5: 50774.19 | H5: Jan | I5: 68 | K5: East | L5: 20 | M5: 19942.01 | N5: 69216.85 | O5: 18 | P5: 14014.85 | Q5: 56815.37 | R5: 14 | S5: 16235.65 | T5: 61216.75 | U5: 24 | V5: 20568.73 | W5: 83898.29 | X5: 14 | Y5: 12232.59 | Z5: 45186.69 | AA5: 90 | AB5: 82993.83 | AC5: 316333.95
A6: East | B6: 316333.95 | D6: Medical Equipment | E6: 58437.9 | H6: Feb | I6: 48 | K6: North | L6: 13 | M6: 14806.11 | N6: 54660.51 | O6: 14 | P6: 11633.8 | Q6: 54381.39 | R6: 17 | S6: 13654.55 | T6: 51629.84 | U6: 20 | V6: 17948.92 | W6: 77453.07 | X6: 11 | Y6: 11279.17 | Z6: 46585.04 | AA6: 75 | AB6: 69322.55 | AC6: 284709.85
A7: Grand Total | B7: 1060251.7 | D7: Pharmaceuticals | E7: 50463.32 | H7: Mar | I7: 40 | K7: South | L7: 12 | M7: 11493.8 | N7: 49810.24 | O7: 12 | P7: 8508.04 | Q7: 40042.19 | R7: 15 | S7: 11388.14 | T7: 52825.37 | U7: 12 | V7: 10877.45 | W7: 44400.26 | X7: 17 | Y7: 14442.08 | Z7: 50818.81 | AA7: 68 | AB7: 56709.51 | AC7: 237896.87
D8: Grand Total | E8: 264031.74 | H8: Qtr2 | I8: 63 | K8: West | L8: 9 | M8: 8422.23 | N8: 33667.08 | O8: 17 | P8: 15535.49 | Q8: 60163.27 | R8: 12 | S8: 9495.85 | T8: 37044.36 | U8: 13 | V8: 9042.8 | W8: 38327.78 | X8: 16 | Y8: 12509.48 | Z8: 52108.58 | AA8: 67 | AB8: 55005.85 | AC8: 221311.07
H9: Apr | I9: 53 | K9: Grand Total | L9: 54 | M9: 54664.15 | N9: 207354.68 | O9: 61 | P9: 49692.18 | Q9: 211402.22 | R9: 58 | S9: 50774.19 | T9: 202716.32 | U9: 69 | V9: 58437.9 | W9: 244079.4 | X9: 58 | Y9: 50463.32 | Z9: 194699.12 | AA9: 300 | AB9: 264031.74 | AC9: 1060251.7
H10: May | I10: 5
H11: Jun | I11: 5
A12: Row Labels | B12: Count of ShipmentID | H12: Qtr3 | I12: 12
A13: Amit Kulkarni | B13: 59 | H13: Jul | I13: 2
A14: Arjun Patel | B14: 59 | H14: Aug | I14: 5
A15: Neha Verma | B15: 63 | H15: Sep | I15: 5
A16: Priya Sharma | B16: 66 | H16: Qtr4 | I16: 8
A17: Rahul Mehta | B17: 53 | H17: Oct | I17: 2
A18: Grand Total | B18: 300 | H18: Nov | I18: 4
H19: Dec | I19: 2
H20: 2026 | I20: 61
H21: Qtr1 | I21: 61
H22: Mar | I22: 61
H23: Grand Total | I23: 300

Sheet Logistics Performance Dashboard
